<mujoco model="K1">
  <compiler angle="radian" meshdir="meshes/" />

  <asset>
    <texture type="skybox" builtin="gradient" rgb1="0.3 0.5 0.7" rgb2="0 0 0" width="512" height="512"/>
    <texture name="texplane" type="2d" builtin="checker" rgb1=".2 .3 .4" rgb2=".1 0.15 0.2" width="512" height="512" mark="cross" markrgb=".8 .8 .8"/>
    <material name="matplane" reflectance="0.3" texture="texplane" texrepeat="1 1" texuniform="true"/>

    <mesh name="Trunk" file="Trunk.STL"/>
    <mesh name="Head_1" file="Head_1.STL"/>
    <mesh name="Head_2" file="Head_2.STL"/>
    <mesh name="Left_Arm_1" file="Left_Arm_1.STL"/>
    <mesh name="Left_Arm_2" file="Left_Arm_2.STL"/>
    <mesh name="Left_Arm_3" file="Left_Arm_3.STL"/>
    <mesh name="Left_Arm_4" file="Left_Arm_4.STL"/>
    <mesh name="Right_Arm_1" file="Right_Arm_1.STL"/>
    <mesh name="Right_Arm_2" file="Right_Arm_2.STL"/>
    <mesh name="Right_Arm_3" file="Right_Arm_3.STL"/>
    <mesh name="Right_Arm_4" file="Right_Arm_4.STL"/>
    <mesh name="Left_Hip_Pitch" file="Left_Hip_Pitch.STL"/>
    <mesh name="Left_Hip_Roll" file="Left_Hip_Roll.STL"/>
    <mesh name="Left_Hip_Yaw" file="Left_Hip_Yaw.STL"/>
    <mesh name="Left_Shank" file="Left_Shank.STL"/>
    <mesh name="Left_Ankle_Cross" file="Left_Ankle_Cross.STL"/>
    <mesh name="Left_Foot" file="Left_Foot.STL"/>
    <mesh name="Right_Hip_Pitch" file="Right_Hip_Pitch.STL"/>
    <mesh name="Right_Hip_Roll" file="Right_Hip_Roll.STL"/>
    <mesh name="Right_Hip_Yaw" file="Right_Hip_Yaw.STL"/>
    <mesh name="Right_Shank" file="Right_Shank.STL"/>
    <mesh name="Right_Ankle_Cross" file="Right_Ankle_Cross.STL"/>
    <mesh name="Right_Foot" file="Right_Foot.STL"/>
  </asset>

  <worldbody>
    <light directional="true" diffuse=".4 .4 .4" specular="0.1 0.1 0.1" pos="0 0 5.0" dir="0 0 -1" castshadow="false" />
    <light directional="true" diffuse=".6 .6 .6" specular="0.2 0.2 0.2" pos="0 0 4" dir="0 0 -1" />
    <geom name="ground" type="plane" pos="0 0 0" size="0 0 1" material="matplane" condim="1"/>

    <body name="Trunk" pos="0 0 0.53">
      <site name='imu' size='0.01' pos='0.0 0.0 0.0' />
      <inertial pos="-0.0043392 -0.00065534 0.065686" quat="0.999896 -0.00411546 0.0137413 -0.00168959" mass="6.3921" diaginertia="0.0962166 0.0895166 0.0201248"/>
      <joint type="free" />
      <geom type="mesh" contype="0" conaffinity="0" group="1" rgba="0.75294 0.75294 0.75294 1" mesh="Trunk"/>
      <geom size="0.06 0.09 0.1" pos="0 0 0.1" type="box" group="3" rgba="0.2 0.8 0.2 0.6"/>
      <geom size="0.05 0.05" pos="0 0 -0.06" quat="0.707105 0.707108 0 0" type="cylinder" group="3" rgba="0.2 0.8 0.2 0.6"/>
      <!-- Visual-only geoms to mirror T1 locomotion ordering -->
      <geom pos="0.0056 0 0.2149" type="mesh" contype="0" conaffinity="0" group="1" rgba="0.75294 0.75294 0.75294 1" mesh="Head_1" />
      <geom pos="0.0056 0 0.2479" type="mesh" contype="0" conaffinity="0" group="1" rgba="0.75294 0.75294 0.75294 1" mesh="Head_2" />
      <geom pos="0 0.077 0.1845" type="mesh" contype="0" conaffinity="0" group="1" rgba="0.75294 0.75294 0.75294 1" mesh="Left_Arm_1" />
      <geom pos="0.0025 0.145 0.171" type="mesh" contype="0" conaffinity="0" group="1" rgba="0.75294 0.75294 0.75294 1" mesh="Left_Arm_2" />
      <geom pos="0.0025 0.189428 0.171" type="mesh" contype="0" conaffinity="0" group="1" rgba="0.75294 0.75294 0.75294 1" mesh="Left_Arm_3" />
      <geom pos="0.0025 0.310928 0.171" type="mesh" contype="0" conaffinity="0" group="1" rgba="0.75294 0.75294 0.75294 1" mesh="Left_Arm_4" />
      <geom pos="0 -0.077 0.1845" type="mesh" contype="0" conaffinity="0" group="1" rgba="0.75294 0.75294 0.75294 1" mesh="Right_Arm_1" />
      <geom pos="0.0025 -0.145 0.171" type="mesh" contype="0" conaffinity="0" group="1" rgba="0.75294 0.75294 0.75294 1" mesh="Right_Arm_2" />
      <geom pos="0.0025 -0.189428 0.171" type="mesh" contype="0" conaffinity="0" group="1" rgba="0.75294 0.75294 0.75294 1" mesh="Right_Arm_3" />
      <geom pos="0.0025 -0.310928 0.171" type="mesh" contype="0" conaffinity="0" group="1" rgba="0.75294 0.75294 0.75294 1" mesh="Right_Arm_4" />

      <!-- Left leg subtree -->
      <body name="Left_Hip_Pitch" pos="0 0.096 -0.062">
        <inertial pos="-0.010093 -0.0019934 -0.024713" quat="0.704206 -0.178798 -0.198986 0.65767" mass="0.64068" diaginertia="0.000987585 0.000880963 0.000503452"/>
        <joint name="Left_Hip_Pitch" pos="0 0 0" axis="0 1 0" range="-2.21 2.21"/>
        <geom type="mesh" contype="0" conaffinity="0" group="1" rgba="0.75294 0.75294 0.75294 1" mesh="Left_Hip_Pitch"/>
        <body name="Left_Hip_Roll" pos="0 0 -0.026">
          <inertial pos="0.023585 0.000049 -0.024996" quat="0.677218 0.203412 0.203412 0.677218" mass="0.127825" diaginertia="0.000262 0.000222694 0.000118306"/>
          <joint name="Left_Hip_Roll" pos="0 0 0" axis="1 0 0" range="-0.4 1.57"/>
          <geom type="mesh" contype="0" conaffinity="0" group="1" rgba="0.75294 0.75294 0.75294 1" mesh="Left_Hip_Roll"/>
          <!-- <geom size="0.036 0.047" quat="0.707105 0 0.707108 0" type="cylinder" group="3" rgba="0.2 0.8 0.2 0.6"/> -->
          <body name="Left_Hip_Yaw" pos="0.012 0 -0.0485">
            <inertial pos="-0.0084744 -0.0040494 -0.087906" quat="0.857995 -0.00590801 -0.0582713 0.510308" mass="1.5591" diaginertia="0.0162716 0.0158564 0.00134895"/>
            <joint name="Left_Hip_Yaw" pos="0 0 0" axis="0 0 1" range="-1 1"/>
            <geom type="mesh" contype="0" conaffinity="0" group="1" rgba="0.75294 0.75294 0.75294 1" mesh="Left_Hip_Yaw"/>
            <geom size="0.04 0.033" pos="0 0 -0.03" type="cylinder" group="3" rgba="0.2 0.8 0.2 0.6"/>
            <body name="Left_Shank" pos="-0.014 0 -0.117">
              <inertial pos="-0.00081083 0.0031459 -0.10922" quat="0.940563 -0.00388906 -0.00385774 0.339574" mass="1.48333" diaginertia="0.0237114 0.0236423 0.00123731"/>
              <joint name="Left_Knee_Pitch" pos="0 0 0" axis="0 1 0" range="0 2.23"/>
              <geom type="mesh" contype="0" conaffinity="0" group="1" rgba="0.75294 0.75294 0.75294 1" mesh="Left_Shank"/>
              <geom size="0.045 0.035" quat="0.707105 0.707108 0 0" type="cylinder" group="3" rgba="0.2 0.8 0.2 0.6"/>
              <geom size="0.03 0.03 0.05" pos="0 0 -0.13" type="box" group="3" rgba="0.2 0.8 0.2 0.6"/>
              <body name="Left_Ankle_Cross" pos="0.00019706 0.0002 -0.24519">
                <inertial pos="0 0 0" quat="0.5 0.5 0.5 0.5" mass="0.038836" diaginertia="4e-06 4e-06 2e-06"/>
                <joint name="Left_Ankle_Pitch" pos="0 0 0" axis="0 1 0" range="-0.87 0.345"/>
                <geom type="mesh" contype="0" conaffinity="0" group="1" rgba="0.75294 0.75294 0.75294 1" mesh="Left_Ankle_Cross"/>
                <body name="left_foot_link" >
                  <inertial pos="7.3589e-05 -4.1141e-06 -0.0075032" quat="0 0.674609 0 0.738175" mass="0.38305" diaginertia="0.000789779 0.000741 0.000197221"/>
                  <joint name="Left_Ankle_Roll" pos="0 0 0" axis="1 0 0" range="-0.345 0.345"/>
                  <geom type="mesh" contype="0" conaffinity="0" group="1" rgba="0.75294 0.75294 0.75294 1" mesh="Left_Foot"/>
                  <geom type="box" pos="0.014 0 -0.008" size="0.08 0.035 0.016" group="3" rgba="0.2 0.8 0.2 0.6"/>
                </body>
              </body>
            </body>
          </body>
        </body>
      </body>

      <!-- Right leg subtree -->
      <body name="Right_Hip_Pitch" pos="0 -0.096 -0.062">
        <inertial pos="-0.010065 0.0020086 -0.024739" quat="0.656712 -0.199052 -0.176963 0.705544" mass="0.6413" diaginertia="0.000988671 0.000880749 0.00050458"/>
        <joint name="Right_Hip_Pitch" pos="0 0 0" axis="0 1 0" range="-2.21 2.21"/>
        <geom type="mesh" contype="0" conaffinity="0" group="1" rgba="0.75294 0.75294 0.75294 1" mesh="Right_Hip_Pitch"/>
        <body name="Right_Hip_Roll" pos="0 0 -0.026">
          <inertial pos="0.023585 0.000049 -0.024996" quat="0.677218 0.203412 0.203412 0.677218" mass="0.127825" diaginertia="0.000262 0.000222694 0.000118306"/>
          <joint name="Right_Hip_Roll" pos="0 0 0" axis="1 0 0" range="-1.57 0.4"/>
          <geom type="mesh" contype="0" conaffinity="0" group="1" rgba="0.75294 0.75294 0.75294 1" mesh="Right_Hip_Roll"/>
          <!-- <geom size="0.036 0.047" quat="0.707105 0 0.707108 0" type="cylinder" group="3" rgba="0.2 0.8 0.2 0.6"/> -->
          <body name="Right_Hip_Yaw" pos="0.012 0 -0.0485">
            <inertial pos="-0.008475 0.0040392 -0.087906" quat="0.510308 -0.0582713 -0.00590801 0.857995" mass="1.5592" diaginertia="0.0162716 0.0158564 0.00134895"/>
            <joint name="Right_Hip_Yaw" pos="0 0 0" axis="0 0 1" range="-1 1"/>
            <geom type="mesh" contype="0" conaffinity="0" group="1" rgba="0.75294 0.75294 0.75294 1" mesh="Right_Hip_Yaw"/>
            <geom size="0.04 0.033" pos="0 0 -0.03" type="cylinder" group="3" rgba="0.2 0.8 0.2 0.6"/>
            <body name="Right_Shank" pos="-0.014 0 -0.117">
              <inertial pos="-0.000805 -0.003146 -0.109215" quat="0.940537 0.00388176 -0.00383651 -0.339646" mass="1.48334" diaginertia="0.0237114 0.0236423 0.00123733"/>
              <joint name="Right_Knee_Pitch" pos="0 0 0" axis="0 1 0" range="0 2.23"/>
              <geom type="mesh" contype="0" conaffinity="0" group="1" rgba="0.75294 0.75294 0.75294 1" mesh="Right_Shank"/>
              <geom size="0.045 0.035" quat="0.707105 0.707108 0 0" type="cylinder" group="3" rgba="0.2 0.8 0.2 0.6"/>
              <geom size="0.03 0.03 0.05" pos="0 0 -0.13" type="box" group="3" rgba="0.2 0.8 0.2 0.6"/>
              <body name="Right_Ankle_Cross" pos="0.00019706 -0.0002 -0.24519">
                <inertial pos="0 0 0" quat="0.5 0.5 0.5 0.5" mass="0.038836" diaginertia="4e-06 4e-06 2e-06"/>
                <joint name="Right_Ankle_Pitch" pos="0 0 0" axis="0 1 0" range="-0.87 0.345"/>
                <geom type="mesh" contype="0" conaffinity="0" group="1" rgba="0.75294 0.75294 0.75294 1" mesh="Right_Ankle_Cross"/>
                <body name="right_foot_link">
                  <inertial pos="-0.000178 -2e-06 -0.007291" quat="0 0.674109 0 0.738632" mass="0.38637" diaginertia="0.000794943 0.000745 0.000200057"/>
                  <joint name="Right_Ankle_Roll" pos="0 0 0" axis="1 0 0" range="-0.345 0.345"/>
                  <geom type="mesh" contype="0" conaffinity="0" group="1" rgba="0.75294 0.75294 0.75294 1" mesh="Right_Foot"/>
                  <geom type="box" pos="0.014 0 -0.008" size="0.08 0.035 0.016" group="3" rgba="0.2 0.8 0.2 0.6"/>
                </body>
              </body>
            </body>
          </body>
        </body>
      </body>
    </body>
  </worldbody>

  <actuator>
    <motor name="Left_Hip_Pitch" joint="Left_Hip_Pitch" ctrllimited="true" ctrlrange="-45.0 45.0" />
    <motor name="Left_Hip_Roll" joint="Left_Hip_Roll" ctrllimited="true" ctrlrange="-30.0 30.0" />
    <motor name="Left_Hip_Yaw" joint="Left_Hip_Yaw" ctrllimited="true" ctrlrange="-30.0 30.0" />
    <motor name="Left_Knee_Pitch" joint="Left_Knee_Pitch" ctrllimited="true" ctrlrange="-45.0 45.0" />
    <motor name="Left_Ankle_Pitch" joint="Left_Ankle_Pitch" ctrllimited="true" ctrlrange="-20.0 20.0" />
    <motor name="Left_Ankle_Roll" joint="Left_Ankle_Roll" ctrllimited="true" ctrlrange="-20.0 20.0" />
    <motor name="Right_Hip_Pitch" joint="Right_Hip_Pitch" ctrllimited="true" ctrlrange="-45.0 45.0" />
    <motor name="Right_Hip_Roll" joint="Right_Hip_Roll" ctrllimited="true" ctrlrange="-30.0 30.0" />
    <motor name="Right_Hip_Yaw" joint="Right_Hip_Yaw" ctrllimited="true" ctrlrange="-30.0 30.0" />
    <motor name="Right_Knee_Pitch" joint="Right_Knee_Pitch" ctrllimited="true" ctrlrange="-45.0 45.0" />
    <motor name="Right_Ankle_Pitch" joint="Right_Ankle_Pitch" ctrllimited="true" ctrlrange="-20.0 20.0" />
    <motor name="Right_Ankle_Roll" joint="Right_Ankle_Roll" ctrllimited="true" ctrlrange="-20.0 20.0" />
  </actuator>

  <sensor>
    <framequat name="orientation" objtype="site" noise="0.001" objname="imu" />
    <gyro name="angular-velocity" site="imu" noise="0.005" />
  </sensor>

</mujoco>


